Workbook

Sheet Index
A1: 2026 | B1: 2025 | C1: 2024 | D1: Other
A2: 2026 | B2: 2025 | C2: 2024 | D2: [Chart1] Monthly Dollars by Sales Representative and Year
A3: 2026 AM Totals | B3: 2025 Adam | C3: 2024 Adam | D3: 2023
A4: 2026 Breakdown | B4: 2025 AM Totals | C4: 2024 AM | D4: Commission Data
A5: 2026 Brett | B5: 2025 Breakdown | C5: 2024 Breakdown | D5: OPs Callback
A6: 2026 Drew | B6: 2025 Brett | C6: 2024 Brett | D6: Paid 2026
A7: 2026 James | B7: 2025 Chris | C7: 2024 Brian | D7: Reports
A8: 2026 Mike | B8: 2025 Drew | C8: 2024 Chris | D8: Surveys
A9: 2026 Surveys | B9: 2025 Geoff | C9: 2024 Insurance vs Retail
B10: 2025 James | C10: 2024 James
B11: 2025 Mike | C11: 2024 Jared
B12: 2025 Will | C12: 2024 Mike
C13: 2024 Schedule
C14: 2024 Will

Sheet 2026
A1: Project # (2164) | B1: Job # | C1: Name | D1: Type | E1: Date | F1: ="Contract Amt $" & TEXT(SUM(F2:F308),"#,##0.00") -> Contract Amt $757,244.55 | G1: Projected Start Date | H1: Projected End Date | I1: AM | J1: ="Invoiced Total $" & TEXT(SUM(J2:J308),"#,##0.00") -> Invoiced Total $253,885.39 | K1: ="Amount Paid $" & TEXT(SUM(K2:K308),"#,##0.00") -> Amount Paid $177,028.67 | L1: ="Change Orders $" & TEXT(SUM(L2:L308),"#,##0.00") -> Change Orders $3,881.10 | M1: ="Cost $" & TEXT(SUM(M2:M308),"#,##0.00") -> Cost $142,694.65 | N1: ="GP $" & TEXT(SUM(N2:N308),"#,##0.00") -> GP $49,902.58 | O1: =AVERAGEIFS(O2:O317, O2:O317, "<>", S2:S317, TRUE) -> 0.66535131 | P1: =AVERAGEIFS(P2:P317, P2:P317, "<>", S2:S317, TRUE) -> 0.67675882 | Q1: =AVERAGEIFS(Q2:Q317, Q2:Q317, "<>", S2:S317, TRUE) -> 0.55698002 | R1: Billed | S1: Paid in Full | T1: Comm Owed | U1: Status | V1: Updated this week | W1: GP | X1: Invoiced | Y1: Contract | Z1: Change Orders | AA1: =IFERROR(__xludf.DUMMYFUNCTION("ARRAYFORMULA({ ""Manager""; IF(A2:A1000="""","""", IF(IFERROR(VALUE(A2:A1000),0)>=1857, ""Drew"", IF( REGEXMATCH( LOWER( TRIM( SUBSTITUTE( SUBSTITUTE( CLEAN(I2:I1000), "&" CHAR(160),"" "" ), CHAR(9),"""" ) ) ), ""^drew$"" ), ""Drew"","""" ) ) ) })"),"Manager") -> Manager | AB1: Amount Paid | AC1: Date of Last Payment
A2: 2162 | B2: 20265001 | C2: Riley Spradlin | E2: 46028 | F2: 49298.62 | G2: 04/02/2026 | H2: 04/02/2026 | I2: Drew | J2: 17603 | K2: 17603 | L2: =if(S2=TRUE,K2-F2,"") | M2: 34751.69 | N2: =if(S2=TRUE,K2-M2,"") | O2: =IF($R2, IFERROR(IF((F2+L2)>0, (F2+L2-M2)/(F2+L2), ""), ""), "") -> 0.29507783 | P2: =IFERROR(__xludf.DUMMYFUNCTION("IF(AND($R2, NOT(REGEXMATCH(UPPER($C2), ""INS""))), IFERROR(IF((F2+L2)>0, (F2+L2-M2)/(F2+L2), """"), """"), """")"),0.29507783382171754) -> 0.29507783 | Q2: =IFERROR(__xludf.DUMMYFUNCTION("IF(AND($R2, REGEXMATCH(UPPER($C2), ""INS"")), IFERROR(IF((F2+L2)>0, (F2+L2-M2)/(F2+L2), """"), """"), """")"),"") | R2: TRUE | S2: FALSE | T2: FALSE | U2: In Billing | V2: FALSE | W2: =O2 -> 0.29507783 | X2: =J2 -> 17603 | Y2: =F2 -> 49298.62 | Z2: =L2 | AA2: =IFERROR(__xludf.DUMMYFUNCTION("""COMPUTED_VALUE"""),"Drew") -> Drew | AB2: =K2 -> 17603
A3: 2154 | B3: 20265002 | C3: Matthew Patton | E3: 46030 | F3: 540 | G3: 03/05/2026 | H3: 03/05/2026 | I3: Brett | J3: 540 | K3: 540 | L3: =if(S3=TRUE,K3-F3,"") -> 0 | M3: 274.35 | N3: =if(S3=TRUE,K3-M3,"") -> 265.65 | O3: =IF($R3, IFERROR(IF((F3+L3)>0, (F3+L3-M3)/(F3+L3), ""), ""), "") -> 0.49194444 | P3: =IFERROR(__xludf.DUMMYFUNCTION("IF(AND($R3, NOT(REGEXMATCH(UPPER($C3), ""INS""))), IFERROR(IF((F3+L3)>0, (F3+L3-M3)/(F3+L3), """"), """"), """")"),0.4919444444444444) -> 0.49194444 | Q3: =IFERROR(__xludf.DUMMYFUNCTION("IF(AND($R3, REGEXMATCH(UPPER($C3), ""INS"")), IFERROR(IF((F3+L3)>0, (F3+L3-M3)/(F3+L3), """"), """"), """")"),"") | R3: TRUE | S3: TRUE | T3: FALSE | U3: In Billing | V3: FALSE | W3: =O3 -> 0.49194444 | X3: =J3 -> 540 | Y3: =F3 -> 540 | Z3: =L3 -> 0 | AA3: =IFERROR(__xludf.DUMMYFUNCTION("""COMPUTED_VALUE"""),"Drew") -> Drew | AB3: =K3 -> 540
A4: 2177 | B4: 20265003 | C4: Marshall Wagner | E4: 46034 | F4: 1182.7 | G4: 01/22/2026 | H4: 01/22/2026 | I4: James | J4: 1182.7 | K4: 1182.7 | L4: =if(S4=TRUE,K4-F4,"") -> 0 | M4: 694.62 | N4: =if(S4=TRUE,K4-M4,"") -> 488.08 | O4: =IF($R4, IFERROR(IF((F4+L4)>0, (F4+L4-M4)/(F4+L4), ""), ""), "") -> 0.41268284 | P4: =IFERROR(__xludf.DUMMYFUNCTION("IF(AND($R4, NOT(REGEXMATCH(UPPER($C4), ""INS""))), IFERROR(IF((F4+L4)>0, (F4+L4-M4)/(F4+L4), """"), """"), """")"),0.4126828443392238) -> 0.41268284 | Q4: =IFERROR(__xludf.DUMMYFUNCTION("IF(AND($R4, REGEXMATCH(UPPER($C4), ""INS"")), IFERROR(IF((F4+L4)>0, (F4+L4-M4)/(F4+L4), """"), """"), """")"),"") | R4: TRUE | S4: TRUE | T4: FALSE | U4: In Billing | V4: FALSE | W4: =O4 -> 0.41268284 | X4: =J4 -> 1182.7 | Y4: =F4 -> 1182.7 | Z4: =L4 -> 0 | AA4: =IFERROR(__xludf.DUMMYFUNCTION("""COMPUTED_VALUE"""),"Drew") -> Drew | AB4: =K4 -> 1182.7
A5: 2173 | B5: 20265004 | C5: Donald Mcghee | E5: 46034 | F5: 522.92 | I5: James | J5: 809.77 | L5: =if(S5=TRUE,K5-F5,"") | M5: 524.7 | N5: =if(S5=TRUE,K5-M5,"") | O5: =IF($R5, IFERROR(IF((F5+L5)>0, (F5+L5-M5)/(F5+L5), ""), ""), "") -> -0.0034039624 | P5: =IFERROR(__xludf.DUMMYFUNCTION("IF(AND($R5, NOT(REGEXMATCH(UPPER($C5), ""INS""))), IFERROR(IF((F5+L5)>0, (F5+L5-M5)/(F5+L5), """"), """"), """")"),-0.003403962365180308) -> -0.0034039624 | Q5: =IFERROR(__xludf.DUMMYFUNCTION("IF(AND($R5, REGEXMATCH(UPPER($C5), ""INS"")), IFERROR(IF((F5+L5)>0, (F5+L5-M5)/(F5+L5), """"), """"), """")"),"") | R5: TRUE | S5: FALSE | T5: FALSE | U5: In Billing | V5: FALSE | W5: =O5 -> -0.0034039624 | X5: =J5 -> 809.77 | Y5: =F5 -> 522.92 | Z5: =L5 | AA5: =IFERROR(__xludf.DUMMYFUNCTION("""COMPUTED_VALUE"""),"Drew") -> Drew | AB5: =K5
A6: 2134 | B6: 20265005 | C6: Shari Dill | E6: 46035 | F6: 2746.93 | G6: 04/02/2026 | H6: 04/02/2026 | I6: James | J6: 2746.93 | K6: 2746.93 | L6: =if(S6=TRUE,K6-F6,"") -> 0 | M6: 2027.7 | N6: =if(S6=TRUE,K6-M6,"") -> 719.23 | O6: =IF($R6, IFERROR(IF((F6+L6)>0, (F6+L6-M6)/(F6+L6), ""), ""), "") -> 0.26183048 | P6: =IFERROR(__xludf.DUMMYFUNCTION("IF(AND($R6, NOT(REGEXMATCH(UPPER($C6), ""INS""))), IFERROR(IF((F6+L6)>0, (F6+L6-M6)/(F6+L6), """"), """"), """")"),0.2618304798447721) -> 0.26183048 | Q6: =IFERROR(__xludf.DUMMYFUNCTION("IF(AND($R6, REGEXMATCH(UPPER($C6), ""INS"")), IFERROR(IF((F6+L6)>0, (F6+L6-M6)/(F6+L6), """"), """"), """")"),"") | R6: TRUE | S6: TRUE | T6: FALSE | U6: Job Scheduled | V6: FALSE | W6: =O6 -> 0.26183048 | X6: =J6 -> 2746.93 | Y6: =F6 -> 2746.93 | Z6: =L6 -> 0 | AA6: =IFERROR(__xludf.DUMMYFUNCTION("""COMPUTED_VALUE"""),"Drew") -> Drew | AB6: =K6 -> 2746.93
A7: 2176 | B7: 20265006 | C7: Nancy Avila | E7: 46045 | F7: 550 | I7: Brett | J7: 550 | K7: 550 | L7: =if(S7=TRUE,K7-F7,"") -> 0 | M7: 250 | N7: =if(S7=TRUE,K7-M7,"") -> 300 | O7: =IF($R7, IFERROR(IF((F7+L7)>0, (F7+L7-M7)/(F7+L7), ""), ""), "") -> 0.54545455 | P7: =IFERROR(__xludf.DUMMYFUNCTION("IF(AND($R7, NOT(REGEXMATCH(UPPER($C7), ""INS""))), IFERROR(IF((F7+L7)>0, (F7+L7-M7)/(F7+L7), """"), """"), """")"),0.5454545454545454) -> 0.54545455 | Q7: =IFERROR(__xludf.DUMMYFUNCTION("IF(AND($R7, REGEXMATCH(UPPER($C7), ""INS"")), IFERROR(IF((F7+L7)>0, (F7+L7-M7)/(F7+L7), """"), """"), """")"),"") | R7: TRUE | S7: TRUE | T7: FALSE | U7: In Billing | V7: FALSE | W7: =O7 -> 0.54545455 | X7: =J7 -> 550 | Y7: =F7 -> 550 | Z7: =L7 -> 0 | AA7: =IFERROR(__xludf.DUMMYFUNCTION("""COMPUTED_VALUE"""),"Drew") -> Drew | AB7: =K7 -> 550
A8: 2197 | B8: 20265007 | C8: James Combs | E8: 46049 | F8: 240 | G8: 01/27/2026 | H8: 01/27/2026 | I8: Adam | J8: 240 | K8: 240 | L8: =if(S8=TRUE,K8-F8,"") -> 0 | M8: 0 | N8: =if(S8=TRUE,K8-M8,"") -> 240 | O8: =IF($R8, IFERROR(IF((F8+L8)>0, (F8+L8-M8)/(F8+L8), ""), ""), "") -> 1 | P8: =IFERROR(__xludf.DUMMYFUNCTION("IF(AND($R8, NOT(REGEXMATCH(UPPER($C8), ""INS""))), IFERROR(IF((F8+L8)>0, (F8+L8-M8)/(F8+L8), """"), """"), """")"),1.0) -> 1 | Q8: =IFERROR(__xludf.DUMMYFUNCTION("IF(AND($R8, REGEXMATCH(UPPER($C8), ""INS"")), IFERROR(IF((F8+L8)>0, (F8+L8-M8)/(F8+L8), """"), """"), """")"),"") | R8: TRUE | S8: TRUE | T8: TRUE | U8: In Billing | V8: FALSE | W8: =O8 -> 1 | X8: =J8 -> 240 | Y8: =F8 -> 240 | Z8: =L8 -> 0 | AA8: =IFERROR(__xludf.DUMMYFUNCTION("""COMPUTED_VALUE"""),"Drew") -> Drew | AB8: =K8 -> 240
A9: 2159 | B9: 20265008 | C9: Jonathan Vernon | E9: 46051 | F9: 9689.68 | I9: James | L9: =if(S9=TRUE,K9-F9,"") | N9: =if(S9=TRUE,K9-M9,"") | O9: =IF($R9, IFERROR(IF((F9+L9)>0, (F9+L9-M9)/(F9+L9), ""), ""), "") | P9: =IFERROR(__xludf.DUMMYFUNCTION("IF(AND($R9, NOT(REGEXMATCH(UPPER($C9), ""INS""))), IFERROR(IF((F9+L9)>0, (F9+L9-M9)/(F9+L9), """"), """"), """")"),"") | Q9: =IFERROR(__xludf.DUMMYFUNCTION("IF(AND($R9, REGEXMATCH(UPPER($C9), ""INS"")), IFERROR(IF((F9+L9)>0, (F9+L9-M9)/(F9+L9), """"), """"), """")"),"") | R9: FALSE | S9: FALSE | T9: FALSE | U9: Materials Ordered | V9: FALSE | W9: =O9 | X9: =J9 | Y9: =F9 -> 9689.68 | Z9: =L9 | AA9: =IFERROR(__xludf.DUMMYFUNCTION("""COMPUTED_VALUE"""),"Drew") -> Drew | AB9: =K9
A10: 2214 | B10: 20265009 | C10: Christian Life Center Emergency Repairs | E10: 46057 | F10: 0 | G10: 02/12/2026 | H10: 02/12/2026 | I10: Chris | J10: 20646.65 | L10: =if(S10=TRUE,K10-F10,"") | M10: 5661.19 | N10: =if(S10=TRUE,K10-M10,"") | O10: =IF($R10, IFERROR(IF((F10+L10)>0, (F10+L10-M10)/(F10+L10), ""), ""), "") | P10: =IFERROR(__xludf.DUMMYFUNCTION("IF(AND($R10, NOT(REGEXMATCH(UPPER($C10), ""INS""))), IFERROR(IF((F10+L10)>0, (F10+L10-M10)/(F10+L10), """"), """"), """")"),"") | Q10: =IFERROR(__xludf.DUMMYFUNCTION("IF(AND($R10, REGEXMATCH(UPPER($C10), ""INS"")), IFERROR(IF((F10+L10)>0, (F10+L10-M10)/(F10+L10), """"), """"), """")"),"") | R10: TRUE | S10: FALSE | T10: FALSE | U10: Job Scheduled | V10: FALSE | W10: =O10 | X10: =J10 -> 20646.65 | Y10: =F10 -> 0 | Z10: =L10 | AA10: =IFERROR(__xludf.DUMMYFUNCTION("""COMPUTED_VALUE"""),"Drew") -> Drew | AB10: =K10
A11: 2192 | B11: 20265010 | C11: Tyler Hunt | E11: 46057 | F11: 32265.41 | G11: 03/19/2026 | H11: 03/19/2026 | I11: James | J11: 32595.41 | K11: 32265.41 | L11: =if(S11=TRUE,K11-F11,"") -> 0 | M11: 20681.57 | N11: =if(S11=TRUE,K11-M11,"") -> 11583.84 | O11: =IF($R11, IFERROR(IF((F11+L11)>0, (F11+L11-M11)/(F11+L11), ""), ""), "") -> 0.35901729 | P11: =IFERROR(__xludf.DUMMYFUNCTION("IF(AND($R11, NOT(REGEXMATCH(UPPER($C11), ""INS""))), IFERROR(IF((F11+L11)>0, (F11+L11-M11)/(F11+L11), """"), """"), """")"),0.3590172881733101) -> 0.35901729 | Q11: =IFERROR(__xludf.DUMMYFUNCTION("IF(AND($R11, REGEXMATCH(UPPER($C11), ""INS"")), IFERROR(IF((F11+L11)>0, (F11+L11-M11)/(F11+L11), """"), """"), """")"),"") | R11: TRUE | S11: TRUE | T11: FALSE | U11: In Billing | V11: FALSE | W11: =O11 -> 0.35901729 | X11: =J11 -> 32595.41 | Y11: =F11 -> 32265.41 | Z11: =L11 -> 0 | AA11: =IFERROR(__xludf.DUMMYFUNCTION("""COMPUTED_VALUE"""),"Drew") -> Drew | AB11: =K11 -> 32265.41
A12: 2168 | B12: 20265011 | C12: August Boehnlein | E12: 46058 | F12: 24299.55 | I12: James | L12: =if(S12=TRUE,K12-F12,"") | N12: =if(S12=TRUE,K12-M12,"") | O12: =IF($R12, IFERROR(IF((F12+L12)>0, (F12+L12-M12)/(F12+L12), ""), ""), "") | P12: =IFERROR(__xludf.DUMMYFUNCTION("IF(AND($R12, NOT(REGEXMATCH(UPPER($C12), ""INS""))), IFERROR(IF((F12+L12)>0, (F12+L12-M12)/(F12+L12), """"), """"), """")"),"") | Q12: =IFERROR(__xludf.DUMMYFUNCTION("IF(AND($R12, REGEXMATCH(UPPER($C12), ""INS"")), IFERROR(IF((F12+L12)>0, (F12+L12-M12)/(F12+L12), """"), """"), """")"),"") | R12: FALSE | S12: FALSE | T12: FALSE | U12: Project On Hold | V12: FALSE | W12: =O12 | X12: =J12 | Y12: =F12 -> 24299.55 | Z12: =L12 | AA12: =IFERROR(__xludf.DUMMYFUNCTION("""COMPUTED_VALUE"""),"Drew") -> Drew | AB12: =K12
A13: 2201 | B13: 20265012 | C13: Deborah Tippie | E13: 46062 | F13: 506.25 | I13: Mike | J13: 506.25 | K13: 506.25 | L13: =if(S13=TRUE,K13-F13,"") -> 0 | N13: =if(S13=TRUE,K13-M13,"") -> 506.25 | O13: =IF($R13, IFERROR(IF((F13+L13)>0, (F13+L13-M13)/(F13+L13), ""), ""), "") -> 1 | P13: =IFERROR(__xludf.DUMMYFUNCTION("IF(AND($R13, NOT(REGEXMATCH(UPPER($C13), ""INS""))), IFERROR(IF((F13+L13)>0, (F13+L13-M13)/(F13+L13), """"), """"), """")"),1.0) -> 1 | Q13: =IFERROR(__xludf.DUMMYFUNCTION("IF(AND($R13, REGEXMATCH(UPPER($C13), ""INS"")), IFERROR(IF((F13+L13)>0, (F13+L13-M13)/(F13+L13), """"), """"), """")"),"") | R13: TRUE | S13: TRUE | T13: FALSE | U13: In Billing | V13: FALSE | W13: =O13 -> 1 | X13: =J13 -> 506.25 | Y13: =F13 -> 506.25 | Z13: =L13 -> 0 | AA13: =IFERROR(__xludf.DUMMYFUNCTION("""COMPUTED_VALUE"""),"Drew") -> Drew | AB13: =K13 -> 506.25
A14: 2012 | B14: 20265013 | C14: INS - Jeremiah Jenkins | E14: 45950 | F14: 0 | G14: 04/09/2026 | H14: 04/09/2026 | I14: James | J14: 17579.32 | K14: 17579.32 | L14: =if(S14=TRUE,K14-F14,"") -> 17579.32 | M14: 15575.98 | N14: =if(S14=TRUE,K14-M14,"") -> 2003.34 | O14: =IF($R14, IFERROR(IF((F14+L14)>0, (F14+L14-M14)/(F14+L14), ""), ""), "") -> 0.11396004 | P14: =IFERROR(__xludf.DUMMYFUNCTION("IF(AND($R14, NOT(REGEXMATCH(UPPER($C14), ""INS""))), IFERROR(IF((F14+L14)>0, (F14+L14-M14)/(F14+L14), """"), """"), """")"),"") | Q14: =IFERROR(__xludf.DUMMYFUNCTION("IF(AND($R14, REGEXMATCH(UPPER($C14), ""INS"")), IFERROR(IF((F14+L14)>0, (F14+L14-M14)/(F14+L14), """"), """"), """")"),0.11396003940994305) -> 0.11396004 | R14: TRUE | S14: TRUE | T14: FALSE | U14: In Progress | V14: FALSE | W14: =O14 -> 0.11396004 | X14: =J14 -> 17579.32 | Y14: =F14 -> 0 | Z14: =L14 -> 17579.32 | AA14: =IFERROR(__xludf.DUMMYFUNCTION("""COMPUTED_VALUE"""),"Drew") -> Drew | AB14: =K14 -> 17579.32
A15: 2229 | B15: 20265014 | C15: INS - Floyd Cain Jr. | E15: 46066 | F15: 0 | I15: James | L15: =if(S15=TRUE,K15-F15,"") | N15: =if(S15=TRUE,K15-M15,"") | O15: =IF($R15, IFERROR(IF((F15+L15)>0, (F15+L15-M15)/(F15+L15), ""), ""), "") | P15: =IFERROR(__xludf.DUMMYFUNCTION("IF(AND($R15, NOT(REGEXMATCH(UPPER($C15), ""INS""))), IFERROR(IF((F15+L15)>0, (F15+L15-M15)/(F15+L15), """"), """"), """")"),"") | Q15: =IFERROR(__xludf.DUMMYFUNCTION("IF(AND($R15, REGEXMATCH(UPPER($C15), ""INS"")), IFERROR(IF((F15+L15)>0, (F15+L15-M15)/(F15+L15), """"), """"), """")"),"") | R15: FALSE | S15: FALSE | T15: FALSE | U15: Approved | V15: FALSE | W15: =O15 | X15: =J15 | Y15: =F15 -> 0 | Z15: =L15 | AA15: =IFERROR(__xludf.DUMMYFUNCTION("""COMPUTED_VALUE"""),"Drew") -> Drew | AB15: =K15
A16: 2180 | B16: 20265015 | C16: Robert Kissell | E16: 46067 | F16: 11560 | I16: Brett | J16: 14167.06 | K16: 14167.06 | L16: =if(S16=TRUE,K16-F16,"") -> 2607.06 | M16: 8890.44 | N16: =if(S16=TRUE,K16-M16,"") -> 5276.62 | O16: =IF($R16, IFERROR(IF((F16+L16)>0, (F16+L16-M16)/(F16+L16), ""), ""), "") -> 0.37245695 | P16: =IFERROR(__xludf.DUMMYFUNCTION("IF(AND($R16, NOT(REGEXMATCH(UPPER($C16), ""INS""))), IFERROR(IF((F16+L16)>0, (F16+L16-M16)/(F16+L16), """"), """"), """")"),0.3724569529598942) -> 0.37245695 | Q16: =IFERROR(__xludf.DUMMYFUNCTION("IF(AND($R16, REGEXMATCH(UPPER($C16), ""INS"")), IFERROR(IF((F16+L16)>0, (F16+L16-M16)/(F16+L16), """"), """"), """")"),"") | R16: TRUE | S16: TRUE | T16: FALSE | U16: In Billing | V16: FALSE | W16: =O16 -> 0.37245695 | X16: =J16 -> 14167.06 | Y16: =F16 -> 11560 | Z16: =L16 -> 2607.06 | AA16: =IFERROR(__xludf.DUMMYFUNCTION("""COMPUTED_VALUE"""),"Drew") -> Drew | AB16: =K16 -> 14167.06
A17: 2221 | B17: 20265016 | C17: Jason Rutan | E17: 46072 | F17: 19468.5 | G17: 04/16/2026 | H17: 04/16/2026 | I17: James | L17: =if(S17=TRUE,K17-F17,"") | N17: =if(S17=TRUE,K17-M17,"") | O17: =IF($R17, IFERROR(IF((F17+L17)>0, (F17+L17-M17)/(F17+L17), ""), ""), "") | P17: =IFERROR(__xludf.DUMMYFUNCTION("IF(AND($R17, NOT(REGEXMATCH(UPPER($C17), ""INS""))), IFERROR(IF((F17+L17)>0, (F17+L17-M17)/(F17+L17), """"), """"), """")"),"") | Q17: =IFERROR(__xludf.DUMMYFUNCTION("IF(AND($R17, REGEXMATCH(UPPER($C17), ""INS"")), IFERROR(IF((F17+L17)>0, (F17+L17-M17)/(F17+L17), """"), """"), """")"),"") | R17: FALSE | S17: FALSE | T17: FALSE | U17: Job Scheduled | V17: FALSE | W17: =O17 | X17: =J17 | Y17: =F17 -> 19468.5 | Z17: =L17 | AA17: =IFERROR(__xludf.DUMMYFUNCTION("""COMPUTED_VALUE"""),"Drew") -> Drew | AB17: =K17
A18: 2052 | B18: 20265017 | C18: Kristen Adams | E18: 46077 | F18: 28121.11 | G18: 04/16/2026 | H18: 04/16/2026 | I18: James | J18: 28320.73 | K18: 28320.73 | L18: =if(S18=TRUE,K18-F18,"") -> 199.62 | M18: 14742.02 | N18: =if(S18=TRUE,K18-M18,"") -> 13578.71 | O18: =IF($R18, IFERROR(IF((F18+L18)>0, (F18+L18-M18)/(F18+L18), ""), ""), "") | P18: =IFERROR(__xludf.DUMMYFUNCTION("IF(AND($R18, NOT(REGEXMATCH(UPPER($C18), ""INS""))), IFERROR(IF((F18+L18)>0, (F18+L18-M18)/(F18+L18), """"), """"), """")"),"") | Q18: =IFERROR(__xludf.DUMMYFUNCTION("IF(AND($R18, REGEXMATCH(UPPER($C18), ""INS"")), IFERROR(IF((F18+L18)>0, (F18+L18-M18)/(F18+L18), """"), """"), """")"),"") | R18: FALSE | S18: TRUE | T18: TRUE | U18: Job Scheduled | V18: FALSE | W18: =O18 | X18: =J18 -> 28320.73 | Y18: =F18 -> 28121.11 | Z18: =L18 -> 199.62 | AA18: =IFERROR(__xludf.DUMMYFUNCTION("""COMPUTED_VALUE"""),"Drew") -> Drew | AB18: =K18 -> 28320.73
A19: 2196 | B19: 20265018 | C19: CHIP - Carol Steed | E19: 46077 | F19: 11265 | G19: 04/16/2026 | H19: 04/16/2026 | I19: James | L19: =if(S19=TRUE,K19-F19,"") | M19: 11562.46 | N19: =if(S19=TRUE,K19-M19,"") | O19: =IF($R19, IFERROR(IF((F19+L19)>0, (F19+L19-M19)/(F19+L19), ""), ""), "") | P19: =IFERROR(__xludf.DUMMYFUNCTION("IF(AND($R19, NOT(REGEXMATCH(UPPER($C19), ""INS""))), IFERROR(IF((F19+L19)>0, (F19+L19-M19)/(F19+L19), """"), """"), """")"),"") | Q19: =IFERROR(__xludf.DUMMYFUNCTION("IF(AND($R19, REGEXMATCH(UPPER($C19), ""INS"")), IFERROR(IF((F19+L19)>0, (F19+L19-M19)/(F19+L19), """"), """"), """")"),"") | R19: FALSE | S19: FALSE | T19: FALSE | U19: Job Scheduled | V19: FALSE | W19: =O19 | X19: =J19 | Y19: =F19 -> 11265 | Z19: =L19 | AA19: =IFERROR(__xludf.DUMMYFUNCTION("""COMPUTED_VALUE"""),"Drew") -> Drew | AB19: =K19
A20: 2209 | B20: 20265019 | C20: Amy Hoff | E20: 46079 | F20: 5480 | G20: 04/16/2026 | H20: 04/16/2026 | I20: Brett | L20: =if(S20=TRUE,K20-F20,"") | N20: =if(S20=TRUE,K20-M20,"") | O20: =IF($R20, IFERROR(IF((F20+L20)>0, (F20+L20-M20)/(F20+L20), ""), ""), "") | P20: =IFERROR(__xludf.DUMMYFUNCTION("IF(AND($R20, NOT(REGEXMATCH(UPPER($C20), ""INS""))), IFERROR(IF((F20+L20)>0, (F20+L20-M20)/(F20+L20), """"), """"), """")"),"") | Q20: =IFERROR(__xludf.DUMMYFUNCTION("IF(AND($R20, REGEXMATCH(UPPER($C20), ""INS"")), IFERROR(IF((F20+L20)>0, (F20+L20-M20)/(F20+L20), """"), """"), """")"),"") | R20: FALSE | S20: FALSE | T20: FALSE | U20: Job Scheduled | V20: FALSE | W20: =O20 | X20: =J20 | Y20: =F20 -> 5480 | Z20: =L20 | AA20: =IFERROR(__xludf.DUMMYFUNCTION("""COMPUTED_VALUE"""),"Drew") -> Drew | AB20: =K20
A21: 2266 | B21: 20265020 | C21: Gianghua Gao | E21: 46080 | F21: 590 | I21: Brett | J21: 590 | K21: 590 | L21: =if(S21=TRUE,K21-F21,"") -> 0 | N21: =if(S21=TRUE,K21-M21,"") -> 590 | O21: =IF($R21, IFERROR(IF((F21+L21)>0, (F21+L21-M21)/(F21+L21), ""), ""), "") -> 1 | P21: =IFERROR(__xludf.DUMMYFUNCTION("IF(AND($R21, NOT(REGEXMATCH(UPPER($C21), ""INS""))), IFERROR(IF((F21+L21)>0, (F21+L21-M21)/(F21+L21), """"), """"), """")"),1.0) -> 1 | Q21: =IFERROR(__xludf.DUMMYFUNCTION("IF(AND($R21, REGEXMATCH(UPPER($C21), ""INS"")), IFERROR(IF((F21+L21)>0, (F21+L21-M21)/(F21+L21), """"), """"), """")"),"") | R21: TRUE | S21: TRUE | T21: FALSE | U21: In Billing | V21: FALSE | W21: =O21 -> 1 | X21: =J21 -> 590 | Y21: =F21 -> 590 | Z21: =L21 -> 0 | AA21: =IFERROR(__xludf.DUMMYFUNCTION("""COMPUTED_VALUE"""),"Drew") -> Drew | AB21: =K21 -> 590
A22: 2002 | B22: 20265021 | C22: Mary Peitsmeyer | E22: 46081 | F22: 17780.69 | G22: 04/16/2026 | H22: 04/16/2026 | I22: Drew | L22: =if(S22=TRUE,K22-F22,"") | N22: =if(S22=TRUE,K22-M22,"") | O22: =IF($R22, IFERROR(IF((F22+L22)>0, (F22+L22-M22)/(F22+L22), ""), ""), "") | P22: =IFERROR(__xludf.DUMMYFUNCTION("IF(AND($R22, NOT(REGEXMATCH(UPPER($C22), ""INS""))), IFERROR(IF((F22+L22)>0, (F22+L22-M22)/(F22+L22), """"), """"), """")"),"") | Q22: =IFERROR(__xludf.DUMMYFUNCTION("IF(AND($R22, REGEXMATCH(UPPER($C22), ""INS"")), IFERROR(IF((F22+L22)>0, (F22+L22-M22)/(F22+L22), """"), """"), """")"),"") | R22: FALSE | S22: FALSE | T22: FALSE | U22: Job Scheduled | V22: FALSE | W22: =O22 | X22: =J22 | Y22: =F22 -> 17780.69 | Z22: =L22 | AA22: =IFERROR(__xludf.DUMMYFUNCTION("""COMPUTED_VALUE"""),"Drew") -> Drew | AB22: =K22
A23: 2257 | B23: 20265022 | C23: James Lintz | E23: 46083 | F23: 590 | G23: 03/12/2026 | H23: 03/12/2026 | I23: Brett | J23: 590 | K23: 590 | L23: =if(S23=TRUE,K23-F23,"") -> 0 | N23: =if(S23=TRUE,K23-M23,"") -> 590 | O23: =IF($R23, IFERROR(IF((F23+L23)>0, (F23+L23-M23)/(F23+L23), ""), ""), "") -> 1 | P23: =IFERROR(__xludf.DUMMYFUNCTION("IF(AND($R23, NOT(REGEXMATCH(UPPER($C23), ""INS""))), IFERROR(IF((F23+L23)>0, (F23+L23-M23)/(F23+L23), """"), """"), """")"),1.0) -> 1 | Q23: =IFERROR(__xludf.DUMMYFUNCTION("IF(AND($R23, REGEXMATCH(UPPER($C23), ""INS"")), IFERROR(IF((F23+L23)>0, (F23+L23-M23)/(F23+L23), """"), """"), """")"),"") | R23: TRUE | S23: TRUE | T23: FALSE | U23: In Billing | V23: FALSE | W23: =O23 -> 1 | X23: =J23 -> 590 | Y23: =F23 -> 590 | Z23: =L23 -> 0 | AA23: =IFERROR(__xludf.DUMMYFUNCTION("""COMPUTED_VALUE"""),"Drew") -> Drew | AB23: =K23 -> 590
A24: 2284 | B24: 20265023 | C24: Jessica Lansford | E24: 46085 | F24: 271.5 | I24: Adam | J24: 271.5 | K24: 271.5 | L24: =if(S24=TRUE,K24-F24,"") -> 0 | M24: 11.25 | N24: =if(S24=TRUE,K24-M24,"") -> 260.25 | O24: =IF($R24, IFERROR(IF((F24+L24)>0, (F24+L24-M24)/(F24+L24), ""), ""), "") -> 0.95856354 | P24: =IFERROR(__xludf.DUMMYFUNCTION("IF(AND($R24, NOT(REGEXMATCH(UPPER($C24), ""INS""))), IFERROR(IF((F24+L24)>0, (F24+L24-M24)/(F24+L24), """"), """"), """")"),0.9585635359116023) -> 0.95856354 | Q24: =IFERROR(__xludf.DUMMYFUNCTION("IF(AND($R24, REGEXMATCH(UPPER($C24), ""INS"")), IFERROR(IF((F24+L24)>0, (F24+L24-M24)/(F24+L24), """"), """"), """")"),"") | R24: TRUE | S24: TRUE | T24: TRUE | U24: In Billing | V24: FALSE | W24: =O24 -> 0.95856354 | X24: =J24 -> 271.5 | Y24: =F24 -> 271.5 | Z24: =L24 -> 0 | AA24: =IFERROR(__xludf.DUMMYFUNCTION("""COMPUTED_VALUE"""),"Drew") -> Drew | AB24: =K24 -> 271.5
A25: 2287 | B25: 20265024 | C25: William Barrett | E25: 46086 | F25: 506.25 | I25: James | J25: 506.25 | K25: 506.25 | L25: =if(S25=TRUE,K25-F25,"") -> 0 | M25: 250 | N25: =if(S25=TRUE,K25-M25,"") -> 256.25 | O25: =IF($R25, IFERROR(IF((F25+L25)>0, (F25+L25-M25)/(F25+L25), ""), ""), "") -> 0.50617284 | P25: =IFERROR(__xludf.DUMMYFUNCTION("IF(AND($R25, NOT(REGEXMATCH(UPPER($C25), ""INS""))), IFERROR(IF((F25+L25)>0, (F25+L25-M25)/(F25+L25), """"), """"), """")"),0.5061728395061729) -> 0.50617284 | Q25: =IFERROR(__xludf.DUMMYFUNCTION("IF(AND($R25, REGEXMATCH(UPPER($C25), ""INS"")), IFERROR(IF((F25+L25)>0, (F25+L25-M25)/(F25+L25), """"), """"), """")"),"") | R25: TRUE | S25: TRUE | T25: FALSE | U25: In Billing | V25: FALSE | W25: =O25 -> 0.50617284 | X25: =J25 -> 506.25 | Y25: =F25 -> 506.25 | Z25: =L25 -> 0 | AA25: =IFERROR(__xludf.DUMMYFUNCTION("""COMPUTED_VALUE"""),"Drew") -> Drew | AB25: =K25 -> 506.25
A26: 1261 | B26: 20265025 | C26: Becky Fiessinger | E26: 46088 | F26: 24570 | G26: 04/09/2026 | H26: 04/09/2026 | I26: Brett | J26: 25560 | K26: 25560 | L26: =if(S26=TRUE,K26-F26,"") -> 990 | M26: 16161.23 | N26: =if(S26=TRUE,K26-M26,"") -> 9398.77 | O26: =IF($R26, IFERROR(IF((F26+L26)>0, (F26+L26-M26)/(F26+L26), ""), ""), "") -> 0.36771401 | P26: =IFERROR(__xludf.DUMMYFUNCTION("IF(AND($R26, NOT(REGEXMATCH(UPPER($C26), ""INS""))), IFERROR(IF((F26+L26)>0, (F26+L26-M26)/(F26+L26), """"), """"), """")"),0.3677140062597809) -> 0.36771401 | Q26: =IFERROR(__xludf.DUMMYFUNCTION("IF(AND($R26, REGEXMATCH(UPPER($C26), ""INS"")), IFERROR(IF((F26+L26)>0, (F26+L26-M26)/(F26+L26), """"), """"), """")"),"") | R26: TRUE | S26: TRUE | T26: FALSE | U26: Job Review | V26: FALSE | W26: =O26 -> 0.36771401 | X26: =J26 -> 25560 | Y26: =F26 -> 24570 | Z26: =L26 -> 990 | AA26: =IFERROR(__xludf.DUMMYFUNCTION("""COMPUTED_VALUE"""),"") | AB26: =K26 -> 25560
A27: 2102 | B27: 20265026 | C27: INS - Josh Gates | E27: 46088 | F27: 0 | I27: James | L27: =if(S27=TRUE,K27-F27,"") | N27: =if(S27=TRUE,K27-M27,"") | O27: =IF($R27, IFERROR(IF((F27+L27)>0, (F27+L27-M27)/(F27+L27), ""), ""), "") | P27: =IFERROR(__xludf.DUMMYFUNCTION("IF(AND($R27, NOT(REGEXMATCH(UPPER($C27), ""INS""))), IFERROR(IF((F27+L27)>0, (F27+L27-M27)/(F27+L27), """"), """"), """")"),"") | Q27: =IFERROR(__xludf.DUMMYFUNCTION("IF(AND($R27, REGEXMATCH(UPPER($C27), ""INS"")), IFERROR(IF((F27+L27)>0, (F27+L27-M27)/(F27+L27), """"), """"), """")"),"") | R27: FALSE | S27: FALSE | T27: FALSE | U27: Approved | V27: FALSE | W27: =O27 | X27: =J27 | Y27: =F27 -> 0 | Z27: =L27 | AA27: =IFERROR(__xludf.DUMMYFUNCTION("""COMPUTED_VALUE"""),"Drew") -> Drew | AB27: =K27
A28: 2288 | B28: 20265027 | C28: John Baumann | E28: 46090 | F28: 0 | I28: Chris | L28: =if(S28=TRUE,K28-F28,"") | N28: =if(S28=TRUE,K28-M28,"") | O28: =IF($R28, IFERROR(IF((F28+L28)>0, (F28+L28-M28)/(F28+L28), ""), ""), "") | P28: =IFERROR(__xludf.DUMMYFUNCTION("IF(AND($R28, NOT(REGEXMATCH(UPPER($C28), ""INS""))), IFERROR(IF((F28+L28)>0, (F28+L28-M28)/(F28+L28), """"), """"), """")"),"") | Q28: =IFERROR(__xludf.DUMMYFUNCTION("IF(AND($R28, REGEXMATCH(UPPER($C28), ""INS"")), IFERROR(IF((F28+L28)>0, (F28+L28-M28)/(F28+L28), """"), """"), """")"),"") | R28: FALSE | S28: FALSE | T28: FALSE | U28: Approved | V28: FALSE | W28: =O28 | X28: =J28 | Y28: =F28 -> 0 | Z28: =L28 | AA28: =IFERROR(__xludf.DUMMYFUNCTION("""COMPUTED_VALUE"""),"Drew") -> Drew | AB28: =K28
A29: 2293 | B29: 20265028 | C29: Andrew Wasouf | E29: 46090 | F29: 593.72 | G29: 03/27/2026 | H29: 03/27/2026 | I29: James | J29: 593.72 | K29: 593.72 | L29: =if(S29=TRUE,K29-F29,"") -> 0 | M29: 293 | N29: =if(S29=TRUE,K29-M29,"") -> 300.72 | O29: =IF($R29, IFERROR(IF((F29+L29)>0, (F29+L29-M29)/(F29+L29), ""), ""), "") -> 0.50650138 | P29: =IFERROR(__xludf.DUMMYFUNCTION("IF(AND($R29, NOT(REGEXMATCH(UPPER($C29), ""INS""))), IFERROR(IF((F29+L29)>0, (F29+L29-M29)/(F29+L29), """"), """"), """")"),0.5065013811224146) -> 0.50650138 | Q29: =IFERROR(__xludf.DUMMYFUNCTION("IF(AND($R29, REGEXMATCH(UPPER($C29), ""INS"")), IFERROR(IF((F29+L29)>0, (F29+L29-M29)/(F29+L29), """"), """"), """")"),"") | R29: TRUE | S29: TRUE | T29: FALSE | U29: In Billing | V29: FALSE | W29: =O29 -> 0.50650138 | X29: =J29 -> 593.72 | Y29: =F29 -> 593.72 | Z29: =L29 -> 0 | AA29: =IFERROR(__xludf.DUMMYFUNCTION("""COMPUTED_VALUE"""),"Drew") -> Drew | AB29: =K29 -> 593.72
A30: 2175 | B30: 20265029 | C30: Joe Fiorita | E30: 46091 | F30: 630 | G30: 04/16/2026 | H30: 04/16/2026 | I30: Brett | J30: 630 | L30: =if(S30=TRUE,K30-F30,"") | M30: 290.67 | N30: =if(S30=TRUE,K30-M30,"") | O30: =IF($R30, IFERROR(IF((F30+L30)>0, (F30+L30-M30)/(F30+L30), ""), ""), "") -> 0.53861905 | P30: =IFERROR(__xludf.DUMMYFUNCTION("IF(AND($R30, NOT(REGEXMATCH(UPPER($C30), ""INS""))), IFERROR(IF((F30+L30)>0, (F30+L30-M30)/(F30+L30), """"), """"), """")"),0.5386190476190476) -> 0.53861905 | Q30: =IFERROR(__xludf.DUMMYFUNCTION("IF(AND($R30, REGEXMATCH(UPPER($C30), ""INS"")), IFERROR(IF((F30+L30)>0, (F30+L30-M30)/(F30+L30), """"), """"), """")"),"") | R30: TRUE | S30: FALSE | T30: FALSE | U30: Job Scheduled | V30: FALSE | W30: =O30 -> 0.53861905 | X30: =J30 -> 630 | Y30: =F30 -> 630 | Z30: =L30 | AA30: =IFERROR(__xludf.DUMMYFUNCTION("""COMPUTED_VALUE"""),"Drew") -> Drew | AB30: =K30
A31: 2301 | B31: 20265030 | C31: INS - Randy Brinkman | E31: 46092 | F31: 0 | I31: James | L31: =if(S31=TRUE,K31-F31,"") | N31: =if(S31=TRUE,K31-M31,"") | O31: =IF($R31, IFERROR(IF((F31+L31)>0, (F31+L31-M31)/(F31+L31), ""), ""), "") | P31: =IFERROR(__xludf.DUMMYFUNCTION("IF(AND($R31, NOT(REGEXMATCH(UPPER($C31), ""INS""))), IFERROR(IF((F31+L31)>0, (F31+L31-M31)/(F31+L31), """"), """"), """")"),"") | Q31: =IFERROR(__xludf.DUMMYFUNCTION("IF(AND($R31, REGEXMATCH(UPPER($C31), ""INS"")), IFERROR(IF((F31+L31)>0, (F31+L31-M31)/(F31+L31), """"), """"), """")"),"") | R31: FALSE | S31: FALSE | T31: FALSE | U31: Approved | V31: FALSE | W31: =O31 | X31: =J31 | Y31: =F31 -> 0 | Z31: =L31 | AA31: =IFERROR(__xludf.DUMMYFUNCTION("""COMPUTED_VALUE"""),"Drew") -> Drew | AB31: =K31
A32: 1344 | B32: 20265031 | C32: INS - Pastor David Douglas's home | E32: 46094 | F32: 33908.02 | I32: Chris | L32: =if(S32=TRUE,K32-F32,"") | N32: =if(S32=TRUE,K32-M32,"") | O32: =IF($R32, IFERROR(IF((F32+L32)>0, (F32+L32-M32)/(F32+L32), ""), ""), "") | P32: =IFERROR(__xludf.DUMMYFUNCTION("IF(AND($R32, NOT(REGEXMATCH(UPPER($C32), ""INS""))), IFERROR(IF((F32+L32)>0, (F32+L32-M32)/(F32+L32), """"), """"), """")"),"") | Q32: =IFERROR(__xludf.DUMMYFUNCTION("IF(AND($R32, REGEXMATCH(UPPER($C32), ""INS"")), IFERROR(IF((F32+L32)>0, (F32+L32-M32)/(F32+L32), """"), """"), """")"),"") | R32: FALSE | S32: FALSE | T32: FALSE | U32: Job Review | V32: FALSE | W32: =O32 | X32: =J32 | Y32: =F32 -> 33908.02 | Z32: =L32 | AA32: =IFERROR(__xludf.DUMMYFUNCTION("""COMPUTED_VALUE"""),"") | AB32: =K32
A33: 2312 | B33: 20265032 | C33: Rachel Conrad | E33: 46094 | F33: 0 | I33: James | L33: =if(S33=TRUE,K33-F33,"") | N33: =if(S33=TRUE,K33-M33,"") | O33: =IF($R33, IFERROR(IF((F33+L33)>0, (F33+L33-M33)/(F33+L33), ""), ""), "") | P33: =IFERROR(__xludf.DUMMYFUNCTION("IF(AND($R33, NOT(REGEXMATCH(UPPER($C33), ""INS""))), IFERROR(IF((F33+L33)>0, (F33+L33-M33)/(F33+L33), """"), """"), """")"),"") | Q33: =IFERROR(__xludf.DUMMYFUNCTION("IF(AND($R33, REGEXMATCH(UPPER($C33), ""INS"")), IFERROR(IF((F33+L33)>0, (F33+L33-M33)/(F33+L33), """"), """"), """")"),"") | R33: FALSE | S33: FALSE | T33: FALSE | U33: Approved | V33: FALSE | W33: =O33 | X33: =J33 | Y33: =F33 -> 0 | Z33: =L33 | AA33: =IFERROR(__xludf.DUMMYFUNCTION("""COMPUTED_VALUE"""),"Drew") -> Drew | AB33: =K33
A34: 2318 | B34: 20265033 | C34: Ralph Lowe | E34: 46094 | F34: 0 | I34: James | L34: =if(S34=TRUE,K34-F34,"") | N34: =if(S34=TRUE,K34-M34,"") | O34: =IF($R34, IFERROR(IF((F34+L34)>0, (F34+L34-M34)/(F34+L34), ""), ""), "") | P34: =IFERROR(__xludf.DUMMYFUNCTION("IF(AND($R34, NOT(REGEXMATCH(UPPER($C34), ""INS""))), IFERROR(IF((F34+L34)>0, (F34+L34-M34)/(F34+L34), """"), """"), """")"),"") | Q34: =IFERROR(__xludf.DUMMYFUNCTION("IF(AND($R34, REGEXMATCH(UPPER($C34), ""INS"")), IFERROR(IF((F34+L34)>0, (F34+L34-M34)/(F34+L34), """"), """"), """")"),"") | R34: FALSE | S34: FALSE | T34: FALSE | U34: Approved | V34: FALSE | W34: =O34 | X34: =J34 | Y34: =F34 -> 0 | Z34: =L34 | AA34: =IFERROR(__xludf.DUMMYFUNCTION("""COMPUTED_VALUE"""),"Drew") -> Drew | AB34: =K34
A35: 2329 | B35: 20265034 | C35: INS - Alicia Luedeke | E35: 46095 | F35: 15106.78 | G35: 04/07/2026 | H35: 04/07/2026 | I35: James | J35: 8340.95 | L35: =if(S35=TRUE,K35-F35,"") | N35: =if(S35=TRUE,K35-M35,"") | O35: =IF($R35, IFERROR(IF((F35+L35)>0, (F35+L35-M35)/(F35+L35), ""), ""), "") -> 1 | P35: =IFERROR(__xludf.DUMMYFUNCTION("IF(AND($R35, NOT(REGEXMATCH(UPPER($C35), ""INS""))), IFERROR(IF((F35+L35)>0, (F35+L35-M35)/(F35+L35), """"), """"), """")"),"") | Q35: =IFERROR(__xludf.DUMMYFUNCTION("IF(AND($R35, REGEXMATCH(UPPER($C35), ""INS"")), IFERROR(IF((F35+L35)>0, (F35+L35-M35)/(F35+L35), """"), """"), """")"),1.0) -> 1 | R35: TRUE | S35: FALSE | T35: FALSE | U35: Job Review | V35: FALSE | W35: =O35 -> 1 | X35: =J35 -> 8340.95 | Y35: =F35 -> 15106.78 | Z35: =L35 | AA35: =IFERROR(__xludf.DUMMYFUNCTION("""COMPUTED_VALUE"""),"Drew") -> Drew | AB35: =K35
A36: 2341 | B36: 20265035 | C36: Grant Pace | E36: 46095 | F36: 17037.2 | G36: 04/30/2026 | H36: 04/29/2026 | I36: James | L36: =if(S36=TRUE,K36-F36,"") | N36: =if(S36=TRUE,K36-M36,"") | O36: =IF($R36, IFERROR(IF((F36+L36)>0, (F36+L36-M36)/(F36+L36), ""), ""), "") | P36: =IFERROR(__xludf.DUMMYFUNCTION("IF(AND($R36, NOT(REGEXMATCH(UPPER($C36), ""INS""))), IFERROR(IF((F36+L36)>0, (F36+L36-M36)/(F36+L36), """"), """"), """")"),"") | Q36: =IFERROR(__xludf.DUMMYFUNCTION("IF(AND($R36, REGEXMATCH(UPPER($C36), ""INS"")), IFERROR(IF((F36+L36)>0, (F36+L36-M36)/(F36+L36), """"), """"), """")"),"") | R36: FALSE | S36: FALSE | T36: FALSE | U36: Job Scheduled | V36: FALSE | W36: =O36 | X36: =J36 | Y36: =F36 -> 17037.2 | Z36: =L36 | AA36: =IFERROR(__xludf.DUMMYFUNCTION("""COMPUTED_VALUE"""),"Drew") -> Drew | AB36: =K36
A37: 2331 | B37: 20265036 | C37: INS - Brady Dowler | E37: 46095 | F37: 0 | I37: Drew | L37: =if(S37=TRUE,K37-F37,"") | N37: =if(S37=TRUE,K37-M37,"") | O37: =IF($R37, IFERROR(IF((F37+L37)>0, (F37+L37-M37)/(F37+L37), ""), ""), "") | P37: =IFERROR(__xludf.DUMMYFUNCTION("IF(AND($R37, NOT(REGEXMATCH(UPPER($C37), ""INS""))), IFERROR(IF((F37+L37)>0, (F37+L37-M37)/(F37+L37), """"), """"), """")"),"") | Q37: =IFERROR(__xludf.DUMMYFUNCTION("IF(AND($R37, REGEXMATCH(UPPER($C37), ""INS"")), IFERROR(IF((F37+L37)>0, (F37+L37-M37)/(F37+L37), """"), """"), """")"),"") | R37: FALSE | S37: FALSE | T37: FALSE | U37: Approved | V37: FALSE | W37: =O37 | X37: =J37 | Y37: =F37 -> 0 | Z37: =L37 | AA37: =IFERROR(__xludf.DUMMYFUNCTION("""COMPUTED_VALUE"""),"Drew") -> Drew | AB37: =K37
A38: 2361 | B38: 20265037 | C38: INS - Chris Browning | E38: 46096 | F38: 0 | I38: Chris | L38: =if(S38=TRUE,K38-F38,"") | N38: =if(S38=TRUE,K38-M38,"") | O38: =IF($R38, IFERROR(IF((F38+L38)>0, (F38+L38-M38)/(F38+L38), ""), ""), "") | P38: =IFERROR(__xludf.DUMMYFUNCTION("IF(AND($R38, NOT(REGEXMATCH(UPPER($C38), ""INS""))), IFERROR(IF((F38+L38)>0, (F38+L38-M38)/(F38+L38), """"), """"), """")"),"") | Q38: =IFERROR(__xludf.DUMMYFUNCTION("IF(AND($R38, REGEXMATCH(UPPER($C38), ""INS"")), IFERROR(IF((F38+L38)>0, (F38+L38-M38)/(F38+L38), """"), """"), """")"),"") | R38: FALSE | S38: FALSE | T38: FALSE | U38: Approved | V38: FALSE | W38: =O38 | X38: =J38 | Y38: =F38 -> 0 | Z38: =L38 | AA38: =IFERROR(__xludf.DUMMYFUNCTION("""COMPUTED_VALUE"""),"Drew") -> Drew | AB38: =K38
A39: 2353 | B39: 20265038 | C39: INS - Matt Clifton | E39: 46096 | F39: 24328.8 | G39: 04/27/2026 | H39: 04/28/2026 | I39: Chris | L39: =if(S39=TRUE,K39-F39,"") | N39: =if(S39=TRUE,K39-M39,"") | O39: =IF($R39, IFERROR(IF((F39+L39)>0, (F39+L39-M39)/(F39+L39), ""), ""), "") | P39: =IFERROR(__xludf.DUMMYFUNCTION("IF(AND($R39, NOT(REGEXMATCH(UPPER($C39), ""INS""))), IFERROR(IF((F39+L39)>0, (F39+L39-M39)/(F39+L39), """"), """"), """")"),"") | Q39: =IFERROR(__xludf.DUMMYFUNCTION("IF(AND($R39, REGEXMATCH(UPPER($C39), ""INS"")), IFERROR(IF((F39+L39)>0, (F39+L39-M39)/(F39+L39), """"), """"), """")"),"") | R39: FALSE | S39: FALSE | T39: FALSE | U39: Job Scheduled | V39: FALSE | W39: =O39 | X39: =J39 | Y39: =F39 -> 24328.8 | Z39: =L39 | AA39: =IFERROR(__xludf.DUMMYFUNCTION("""COMPUTED_VALUE"""),"Drew") -> Drew | AB39: =K39
A40: 2364 | B40: 20265039 | C40: Jason Schaefer | E40: 46096 | F40: 0 | I40: James | L40: =if(S40=TRUE,K40-F40,"") | N40: =if(S40=TRUE,K40-M40,"") | O40: =IF($R40, IFERROR(IF((F40+L40)>0, (F40+L40-M40)/(F40+L40), ""), ""), "") | P40: =IFERROR(__xludf.DUMMYFUNCTION("IF(AND($R40, NOT(REGEXMATCH(UPPER($C40), ""INS""))), IFERROR(IF((F40+L40)>0, (F40+L40-M40)/(F40+L40), """"), """"), """")"),"") | Q40: =IFERROR(__xludf.DUMMYFUNCTION("IF(AND($R40, REGEXMATCH(UPPER($C40), ""INS"")), IFERROR(IF((F40+L40)>0, (F40+L40-M40)/(F40+L40), """"), """"), """")"),"") | R40: FALSE | S40: FALSE | T40: FALSE | U40: Approved | V40: FALSE | W40: =O40 | X40: =J40 | Y40: =F40 -> 0 | Z40: =L40 | AA40: =IFERROR(__xludf.DUMMYFUNCTION("""COMPUTED_VALUE"""),"Drew") -> Drew | AB40: =K40
...

Sheet 2026 Breakdown

Sheet 2026 AM Totals
J1: Av per Contract | K1: Open Jobs
J2: =E2/B2 -> 255.75 | K2: =COUNTIFS('2026'!I:I,"Adam",'2026'!U:U,"<>In Billing") -> 0
J3: =E3/B3 -> 2658.74 | K3: =COUNTIFS('2026'!I:I,"Brett",'2026'!U:U,"<>In Billing") -> 18
J4: =E4/B4 -> 9023.86 | K4: =COUNTIFS('2026'!I:I,"Chris",'2026'!U:U,"<>In Billing") -> 14
J5: =E5/B5 -> 6467.3 | K5: =COUNTIFS('2026'!I:I,"Drew",'2026'!U:U,"<>In Billing") -> 11
J6: =E6/B6 -> 6319.3333 | K6: =COUNTIFS('2026'!I:I,"James",'2026'!U:U,"<>In Billing") -> 49
J7: =E7/B7 -> 6781.6147 | K7: =COUNTIFS('2026'!I:I,"Mike",'2026'!U:U,"<>In Billing") -> 12
J8: =AVERAGE(J2:J7) -> 5251.0997 | K8: =SUM(K2:K7) -> 104

Sheet 2026 Brett
J1: Commission Paid | K1: Commission Owed | L1: Owed has been paid | M1: Manual Override
J2: {=IFERROR(INDEX('Commission Data'!$D:$D,MATCH(1,('Commission Data'!$B:$B=A2)*('Commission Data'!$C:$C="Brett"),0)),0)} -> 27 | K2: {=IFERROR(INDEX('Commission Data'!$E:$E,MATCH(1,('Commission Data'!$B:$B=A2)*('Commission Data'!$C:$C="Brett"),0)),0)} -> 0 | L2: FALSE | M2: FALSE
J3: {=IFERROR(INDEX('Commission Data'!$D:$D,MATCH(1,('Commission Data'!$B:$B=A3)*('Commission Data'!$C:$C="Brett"),0)),0)} -> 27.5 | K3: {=IFERROR(INDEX('Commission Data'!$E:$E,MATCH(1,('Commission Data'!$B:$B=A3)*('Commission Data'!$C:$C="Brett"),0)),0)} -> 0 | L3: FALSE | M3: FALSE
J4: {=IFERROR(INDEX('Commission Data'!$D:$D,MATCH(1,('Commission Data'!$B:$B=A4)*('Commission Data'!$C:$C="Brett"),0)),0)} -> 708.35 | K4: {=IFERROR(INDEX('Commission Data'!$E:$E,MATCH(1,('Commission Data'!$B:$B=A4)*('Commission Data'!$C:$C="Brett"),0)),0)} -> 0 | L4: FALSE | M4: FALSE
J5: {=IFERROR(INDEX('Commission Data'!$D:$D,MATCH(1,('Commission Data'!$B:$B=A5)*('Commission Data'!$C:$C="Brett"),0)),0)} -> 0 | K5: {=IFERROR(INDEX('Commission Data'!$E:$E,MATCH(1,('Commission Data'!$B:$B=A5)*('Commission Data'!$C:$C="Brett"),0)),0)} -> 0 | L5: FALSE | M5: FALSE
J6: {=IFERROR(INDEX('Commission Data'!$D:$D,MATCH(1,('Commission Data'!$B:$B=A6)*('Commission Data'!$C:$C="Brett"),0)),0)} -> 29.5 | K6: {=IFERROR(INDEX('Commission Data'!$E:$E,MATCH(1,('Commission Data'!$B:$B=A6)*('Commission Data'!$C:$C="Brett"),0)),0)} -> 0 | L6: FALSE | M6: FALSE
J7: {=IFERROR(INDEX('Commission Data'!$D:$D,MATCH(1,('Commission Data'!$B:$B=A7)*('Commission Data'!$C:$C="Brett"),0)),0)} -> 29.5 | K7: {=IFERROR(INDEX('Commission Data'!$E:$E,MATCH(1,('Commission Data'!$B:$B=A7)*('Commission Data'!$C:$C="Brett"),0)),0)} -> 0 | L7: FALSE | M7: FALSE
J8: {=IFERROR(INDEX('Commission Data'!$D:$D,MATCH(1,('Commission Data'!$B:$B=A8)*('Commission Data'!$C:$C="Brett"),0)),0)} -> 1278 | K8: {=IFERROR(INDEX('Commission Data'!$E:$E,MATCH(1,('Commission Data'!$B:$B=A8)*('Commission Data'!$C:$C="Brett"),0)),0)} -> 0 | L8: FALSE | M8: FALSE
J9: {=IFERROR(INDEX('Commission Data'!$D:$D,MATCH(1,('Commission Data'!$B:$B=A9)*('Commission Data'!$C:$C="Brett"),0)),0)} -> 0 | K9: {=IFERROR(INDEX('Commission Data'!$E:$E,MATCH(1,('Commission Data'!$B:$B=A9)*('Commission Data'!$C:$C="Brett"),0)),0)} -> 0 | L9: FALSE | M9: FALSE
J10: {=IFERROR(INDEX('Commission Data'!$D:$D,MATCH(1,('Commission Data'!$B:$B=A10)*('Commission Data'!$C:$C="Brett"),0)),0)} -> 0 | K10: {=IFERROR(INDEX('Commission Data'!$E:$E,MATCH(1,('Commission Data'!$B:$B=A10)*('Commission Data'!$C:$C="Brett"),0)),0)} -> 0 | L10: FALSE | M10: FALSE
J11: {=IFERROR(INDEX('Commission Data'!$D:$D,MATCH(1,('Commission Data'!$B:$B=A11)*('Commission Data'!$C:$C="Brett"),0)),0)} -> 0 | K11: {=IFERROR(INDEX('Commission Data'!$E:$E,MATCH(1,('Commission Data'!$B:$B=A11)*('Commission Data'!$C:$C="Brett"),0)),0)} -> 0 | L11: FALSE | M11: FALSE
J12: {=IFERROR(INDEX('Commission Data'!$D:$D,MATCH(1,('Commission Data'!$B:$B=A12)*('Commission Data'!$C:$C="Brett"),0)),0)} -> 0 | K12: {=IFERROR(INDEX('Commission Data'!$E:$E,MATCH(1,('Commission Data'!$B:$B=A12)*('Commission Data'!$C:$C="Brett"),0)),0)} -> 0 | L12: FALSE | M12: FALSE
J13: {=IFERROR(INDEX('Commission Data'!$D:$D,MATCH(1,('Commission Data'!$B:$B=A13)*('Commission Data'!$C:$C="Brett"),0)),0)} -> 0 | K13: {=IFERROR(INDEX('Commission Data'!$E:$E,MATCH(1,('Commission Data'!$B:$B=A13)*('Commission Data'!$C:$C="Brett"),0)),0)} -> 0 | L13: FALSE | M13: FALSE
... J101: {=IFERROR(INDEX('Commission Data'!$D:$D,MATCH(1,('Commission Data'!$B:$B=A101)*('Commission Data'!$C:$C="Brett"),0)),0)} -> 0 | K101: {=IFERROR(INDEX('Commission Data'!$E:$E,MATCH(1,('Commission Data'!$B:$B=A101)*('Commission Data'!$C:$C="Brett"),0)),0)} -> 0 | L101: FALSE | M101: FALSE

Sheet 2026 Drew
J1: Commission Paid | K1: Commission Owed | L1: Owed has been paid | M1: Manual Override
J2: {=IFERROR(INDEX('Commission Data'!$D:$D,MATCH(1,('Commission Data'!$B:$B=A2)*('Commission Data'!$C:$C="Drew"),0)),0)} -> 176.03 | K2: {=IFERROR(INDEX('Commission Data'!$E:$E,MATCH(1,('Commission Data'!$B:$B=A2)*('Commission Data'!$C:$C="Drew"),0)),0)} -> 0 | L2: FALSE | M2: FALSE
J3: {=IFERROR(INDEX('Commission Data'!$D:$D,MATCH(1,('Commission Data'!$B:$B=A3)*('Commission Data'!$C:$C="Drew"),0)),0)} -> 5.4 | K3: {=IFERROR(INDEX('Commission Data'!$E:$E,MATCH(1,('Commission Data'!$B:$B=A3)*('Commission Data'!$C:$C="Drew"),0)),0)} -> 0 | L3: FALSE | M3: FALSE
J4: {=IFERROR(INDEX('Commission Data'!$D:$D,MATCH(1,('Commission Data'!$B:$B=A4)*('Commission Data'!$C:$C="Drew"),0)),0)} -> 11.83 | K4: {=IFERROR(INDEX('Commission Data'!$E:$E,MATCH(1,('Commission Data'!$B:$B=A4)*('Commission Data'!$C:$C="Drew"),0)),0)} -> 0 | L4: FALSE | M4: FALSE
J5: {=IFERROR(INDEX('Commission Data'!$D:$D,MATCH(1,('Commission Data'!$B:$B=A5)*('Commission Data'!$C:$C="Drew"),0)),0)} -> 0 | K5: {=IFERROR(INDEX('Commission Data'!$E:$E,MATCH(1,('Commission Data'!$B:$B=A5)*('Commission Data'!$C:$C="Drew"),0)),0)} -> 0 | L5: FALSE | M5: FALSE
J6: {=IFERROR(INDEX('Commission Data'!$D:$D,MATCH(1,('Commission Data'!$B:$B=A6)*('Commission Data'!$C:$C="Drew"),0)),0)} -> 27.47 | K6: {=IFERROR(INDEX('Commission Data'!$E:$E,MATCH(1,('Commission Data'!$B:$B=A6)*('Commission Data'!$C:$C="Drew"),0)),0)} -> 0 | L6: FALSE | M6: FALSE
J7: {=IFERROR(INDEX('Commission Data'!$D:$D,MATCH(1,('Commission Data'!$B:$B=A7)*('Commission Data'!$C:$C="Drew"),0)),0)} -> 5.5 | K7: {=IFERROR(INDEX('Commission Data'!$E:$E,MATCH(1,('Commission Data'!$B:$B=A7)*('Commission Data'!$C:$C="Drew"),0)),0)} -> 0 | L7: FALSE | M7: FALSE
J8: {=IFERROR(INDEX('Commission Data'!$D:$D,MATCH(1,('Commission Data'!$B:$B=A8)*('Commission Data'!$C:$C="Drew"),0)),0)} -> 0 | K8: {=IFERROR(INDEX('Commission Data'!$E:$E,MATCH(1,('Commission Data'!$B:$B=A8)*('Commission Data'!$C:$C="Drew"),0)),0)} -> 2.4 | L8: FALSE | M8: FALSE
J9: {=IFERROR(INDEX('Commission Data'!$D:$D,MATCH(1,('Commission Data'!$B:$B=A9)*('Commission Data'!$C:$C="Drew"),0)),0)} -> 0 | K9: {=IFERROR(INDEX('Commission Data'!$E:$E,MATCH(1,('Commission Data'!$B:$B=A9)*('Commission Data'!$C:$C="Drew"),0)),0)} -> 0 | L9: FALSE | M9: FALSE
J10: {=IFERROR(INDEX('Commission Data'!$D:$D,MATCH(1,('Commission Data'!$B:$B=A10)*('Commission Data'!$C:$C="Drew"),0)),0)} -> 0 | K10: {=IFERROR(INDEX('Commission Data'!$E:$E,MATCH(1,('Commission Data'!$B:$B=A10)*('Commission Data'!$C:$C="Drew"),0)),0)} -> 0 | L10: FALSE | M10: FALSE
J11: {=IFERROR(INDEX('Commission Data'!$D:$D,MATCH(1,('Commission Data'!$B:$B=A11)*('Commission Data'!$C:$C="Drew"),0)),0)} -> 322.65 | K11: {=IFERROR(INDEX('Commission Data'!$E:$E,MATCH(1,('Commission Data'!$B:$B=A11)*('Commission Data'!$C:$C="Drew"),0)),0)} -> 0 | L11: FALSE | M11: FALSE
J12: {=IFERROR(INDEX('Commission Data'!$D:$D,MATCH(1,('Commission Data'!$B:$B=A12)*('Commission Data'!$C:$C="Drew"),0)),0)} -> 0 | K12: {=IFERROR(INDEX('Commission Data'!$E:$E,MATCH(1,('Commission Data'!$B:$B=A12)*('Commission Data'!$C:$C="Drew"),0)),0)} -> 0 | L12: FALSE | M12: FALSE
J13: {=IFERROR(INDEX('Commission Data'!$D:$D,MATCH(1,('Commission Data'!$B:$B=A13)*('Commission Data'!$C:$C="Drew"),0)),0)} -> 5.06 | K13: {=IFERROR(INDEX('Commission Data'!$E:$E,MATCH(1,('Commission Data'!$B:$B=A13)*('Commission Data'!$C:$C="Drew"),0)),0)} -> 0 | L13: FALSE | M13: FALSE
... J400: {=IFERROR(INDEX('Commission Data'!$D:$D,MATCH(1,('Commission Data'!$B:$B=A400)*('Commission Data'!$C:$C="Drew"),0)),0)} -> 0 | K400: {=IFERROR(INDEX('Commission Data'!$E:$E,MATCH(1,('Commission Data'!$B:$B=A400)*('Commission Data'!$C:$C="Drew"),0)),0)} -> 0 | L400: FALSE | M400: FALSE

Sheet 2026 James
J1: Commission Paid | K1: Commission Owed | L1: Owed has been paid | M1: Manual Override
J2: {=IFERROR(INDEX('Commission Data'!$D:$D,MATCH(1,('Commission Data'!$B:$B=A2)*('Commission Data'!$C:$C="James"),0)),0)} -> 118.27 | K2: {=IFERROR(INDEX('Commission Data'!$E:$E,MATCH(1,('Commission Data'!$B:$B=A2)*('Commission Data'!$C:$C="James"),0)),0)} -> 0 | L2: FALSE | M2: FALSE
J3: {=IFERROR(INDEX('Commission Data'!$D:$D,MATCH(1,('Commission Data'!$B:$B=A3)*('Commission Data'!$C:$C="James"),0)),0)} -> 0 | K3: {=IFERROR(INDEX('Commission Data'!$E:$E,MATCH(1,('Commission Data'!$B:$B=A3)*('Commission Data'!$C:$C="James"),0)),0)} -> 0 | L3: FALSE | M3: FALSE
J4: {=IFERROR(INDEX('Commission Data'!$D:$D,MATCH(1,('Commission Data'!$B:$B=A4)*('Commission Data'!$C:$C="James"),0)),0)} -> 274.69 | K4: {=IFERROR(INDEX('Commission Data'!$E:$E,MATCH(1,('Commission Data'!$B:$B=A4)*('Commission Data'!$C:$C="James"),0)),0)} -> 0 | L4: FALSE | M4: FALSE
J5: {=IFERROR(INDEX('Commission Data'!$D:$D,MATCH(1,('Commission Data'!$B:$B=A5)*('Commission Data'!$C:$C="James"),0)),0)} -> 0 | K5: {=IFERROR(INDEX('Commission Data'!$E:$E,MATCH(1,('Commission Data'!$B:$B=A5)*('Commission Data'!$C:$C="James"),0)),0)} -> 0 | L5: FALSE | M5: FALSE
J6: {=IFERROR(INDEX('Commission Data'!$D:$D,MATCH(1,('Commission Data'!$B:$B=A6)*('Commission Data'!$C:$C="James"),0)),0)} -> 3226.54 | K6: {=IFERROR(INDEX('Commission Data'!$E:$E,MATCH(1,('Commission Data'!$B:$B=A6)*('Commission Data'!$C:$C="James"),0)),0)} -> 0 | L6: FALSE | M6: FALSE
J7: {=IFERROR(INDEX('Commission Data'!$D:$D,MATCH(1,('Commission Data'!$B:$B=A7)*('Commission Data'!$C:$C="James"),0)),0)} -> 0 | K7: {=IFERROR(INDEX('Commission Data'!$E:$E,MATCH(1,('Commission Data'!$B:$B=A7)*('Commission Data'!$C:$C="James"),0)),0)} -> 0 | L7: FALSE | M7: FALSE
J8: {=IFERROR(INDEX('Commission Data'!$D:$D,MATCH(1,('Commission Data'!$B:$B=A8)*('Commission Data'!$C:$C="James"),0)),0)} -> 1757.93 | K8: {=IFERROR(INDEX('Commission Data'!$E:$E,MATCH(1,('Commission Data'!$B:$B=A8)*('Commission Data'!$C:$C="James"),0)),0)} -> 0 | L8: FALSE | M8: FALSE
J9: {=IFERROR(INDEX('Commission Data'!$D:$D,MATCH(1,('Commission Data'!$B:$B=A9)*('Commission Data'!$C:$C="James"),0)),0)} -> 0 | K9: {=IFERROR(INDEX('Commission Data'!$E:$E,MATCH(1,('Commission Data'!$B:$B=A9)*('Commission Data'!$C:$C="James"),0)),0)} -> 0 | L9: FALSE | M9: FALSE
J10: {=IFERROR(INDEX('Commission Data'!$D:$D,MATCH(1,('Commission Data'!$B:$B=A10)*('Commission Data'!$C:$C="James"),0)),0)} -> 0 | K10: {=IFERROR(INDEX('Commission Data'!$E:$E,MATCH(1,('Commission Data'!$B:$B=A10)*('Commission Data'!$C:$C="James"),0)),0)} -> 0 | L10: FALSE | M10: FALSE
J11: {=IFERROR(INDEX('Commission Data'!$D:$D,MATCH(1,('Commission Data'!$B:$B=A11)*('Commission Data'!$C:$C="James"),0)),0)} -> 2428.01 | K11: {=IFERROR(INDEX('Commission Data'!$E:$E,MATCH(1,('Commission Data'!$B:$B=A11)*('Commission Data'!$C:$C="James"),0)),0)} -> 404.06 | L11: FALSE | M11: FALSE
J12: {=IFERROR(INDEX('Commission Data'!$D:$D,MATCH(1,('Commission Data'!$B:$B=A12)*('Commission Data'!$C:$C="James"),0)),0)} -> 0 | K12: {=IFERROR(INDEX('Commission Data'!$E:$E,MATCH(1,('Commission Data'!$B:$B=A12)*('Commission Data'!$C:$C="James"),0)),0)} -> 0 | L12: FALSE | M12: FALSE
J13: {=IFERROR(INDEX('Commission Data'!$D:$D,MATCH(1,('Commission Data'!$B:$B=A13)*('Commission Data'!$C:$C="James"),0)),0)} -> 50.63 | K13: {=IFERROR(INDEX('Commission Data'!$E:$E,MATCH(1,('Commission Data'!$B:$B=A13)*('Commission Data'!$C:$C="James"),0)),0)} -> 0 | L13: FALSE | M13: FALSE
... J201: {=IFERROR(INDEX('Commission Data'!$D:$D,MATCH(1,('Commission Data'!$B:$B=A201)*('Commission Data'!$C:$C="James"),0)),0)} -> 0 | K201: {=IFERROR(INDEX('Commission Data'!$E:$E,MATCH(1,('Commission Data'!$B:$B=A201)*('Commission Data'!$C:$C="James"),0)),0)} -> 0 | L201: FALSE | M201: FALSE

Sheet 2026 Mike
J1: Commission Paid | K1: Commission Owed | L1: Owed has been paid | M1: Manual Override
J2: {=IFERROR(INDEX('Commission Data'!$D:$D,MATCH(1,('Commission Data'!$B:$B=A2)*('Commission Data'!$C:$C="Mike"),0)),0)} -> 25.31 | K2: {=IFERROR(INDEX('Commission Data'!$E:$E,MATCH(1,('Commission Data'!$B:$B=A2)*('Commission Data'!$C:$C="Mike"),0)),0)} -> 0 | L2: FALSE | M2: FALSE
J3: {=IFERROR(INDEX('Commission Data'!$D:$D,MATCH(1,('Commission Data'!$B:$B=A3)*('Commission Data'!$C:$C="Mike"),0)),0)} -> 0 | K3: {=IFERROR(INDEX('Commission Data'!$E:$E,MATCH(1,('Commission Data'!$B:$B=A3)*('Commission Data'!$C:$C="Mike"),0)),0)} -> 0 | L3: FALSE | M3: FALSE
J4: {=IFERROR(INDEX('Commission Data'!$D:$D,MATCH(1,('Commission Data'!$B:$B=A4)*('Commission Data'!$C:$C="Mike"),0)),0)} -> 0 | K4: {=IFERROR(INDEX('Commission Data'!$E:$E,MATCH(1,('Commission Data'!$B:$B=A4)*('Commission Data'!$C:$C="Mike"),0)),0)} -> 0 | L4: FALSE | M4: FALSE
J5: {=IFERROR(INDEX('Commission Data'!$D:$D,MATCH(1,('Commission Data'!$B:$B=A5)*('Commission Data'!$C:$C="Mike"),0)),0)} -> 0 | K5: {=IFERROR(INDEX('Commission Data'!$E:$E,MATCH(1,('Commission Data'!$B:$B=A5)*('Commission Data'!$C:$C="Mike"),0)),0)} -> 0 | L5: FALSE | M5: FALSE
J6: {=IFERROR(INDEX('Commission Data'!$D:$D,MATCH(1,('Commission Data'!$B:$B=A6)*('Commission Data'!$C:$C="Mike"),0)),0)} -> 0 | K6: {=IFERROR(INDEX('Commission Data'!$E:$E,MATCH(1,('Commission Data'!$B:$B=A6)*('Commission Data'!$C:$C="Mike"),0)),0)} -> 0 | L6: FALSE | M6: FALSE
J7: {=IFERROR(INDEX('Commission Data'!$D:$D,MATCH(1,('Commission Data'!$B:$B=A7)*('Commission Data'!$C:$C="Mike"),0)),0)} -> 0 | K7: {=IFERROR(INDEX('Commission Data'!$E:$E,MATCH(1,('Commission Data'!$B:$B=A7)*('Commission Data'!$C:$C="Mike"),0)),0)} -> 0 | L7: FALSE | M7: FALSE
J8: {=IFERROR(INDEX('Commission Data'!$D:$D,MATCH(1,('Commission Data'!$B:$B=A8)*('Commission Data'!$C:$C="Mike"),0)),0)} -> 0 | K8: {=IFERROR(INDEX('Commission Data'!$E:$E,MATCH(1,('Commission Data'!$B:$B=A8)*('Commission Data'!$C:$C="Mike"),0)),0)} -> 0 | L8: FALSE | M8: FALSE
J9: {=IFERROR(INDEX('Commission Data'!$D:$D,MATCH(1,('Commission Data'!$B:$B=A9)*('Commission Data'!$C:$C="Mike"),0)),0)} -> 0 | K9: {=IFERROR(INDEX('Commission Data'!$E:$E,MATCH(1,('Commission Data'!$B:$B=A9)*('Commission Data'!$C:$C="Mike"),0)),0)} -> 0 | L9: FALSE | M9: FALSE
J10: {=IFERROR(INDEX('Commission Data'!$D:$D,MATCH(1,('Commission Data'!$B:$B=A10)*('Commission Data'!$C:$C="Mike"),0)),0)} -> 0 | K10: {=IFERROR(INDEX('Commission Data'!$E:$E,MATCH(1,('Commission Data'!$B:$B=A10)*('Commission Data'!$C:$C="Mike"),0)),0)} -> 0 | L10: FALSE | M10: FALSE
J11: {=IFERROR(INDEX('Commission Data'!$D:$D,MATCH(1,('Commission Data'!$B:$B=A11)*('Commission Data'!$C:$C="Mike"),0)),0)} -> 0 | K11: {=IFERROR(INDEX('Commission Data'!$E:$E,MATCH(1,('Commission Data'!$B:$B=A11)*('Commission Data'!$C:$C="Mike"),0)),0)} -> 0 | L11: FALSE | M11: FALSE
J12: {=IFERROR(INDEX('Commission Data'!$D:$D,MATCH(1,('Commission Data'!$B:$B=A12)*('Commission Data'!$C:$C="Mike"),0)),0)} -> 0 | K12: {=IFERROR(INDEX('Commission Data'!$E:$E,MATCH(1,('Commission Data'!$B:$B=A12)*('Commission Data'!$C:$C="Mike"),0)),0)} -> 0 | L12: FALSE | M12: FALSE
J13: {=IFERROR(INDEX('Commission Data'!$D:$D,MATCH(1,('Commission Data'!$B:$B=A13)*('Commission Data'!$C:$C="Mike"),0)),0)} -> 0 | K13: {=IFERROR(INDEX('Commission Data'!$E:$E,MATCH(1,('Commission Data'!$B:$B=A13)*('Commission Data'!$C:$C="Mike"),0)),0)} -> 0 | L13: FALSE | M13: FALSE
... J101: {=IFERROR(INDEX('Commission Data'!$D:$D,MATCH(1,('Commission Data'!$B:$B=A101)*('Commission Data'!$C:$C="Mike"),0)),0)} -> 0 | K101: {=IFERROR(INDEX('Commission Data'!$E:$E,MATCH(1,('Commission Data'!$B:$B=A101)*('Commission Data'!$C:$C="Mike"),0)),0)} -> 0 | L101: FALSE | M101: FALSE

Sheet Paid 2026
A1: 2026-01
A2: Job Number | B2: Name | C2: Contract Amount | D2: Change Orders | E2: Invoiced Total | F2: Cost | G2: GP | H2: GP % | I2: Paid in Full
A3: 20255005 | B3: INS - Stephanie Quintor | C3: 26697.13 | D3: 21916.54 | E3: 36000 | F3: 18394.18 | G3: 30219.49 | H3: 0.62162536 | I3: TRUE
A4: 20255063 | B4: INS - Glen Shelley | C4: 12550.85 | D4: 3160.77 | E4: 11109.02 | F4: 8075.9 | G4: 7635.72 | H4: 0.4859919 | I4: TRUE
A5: 20255069 | B5: INS - New Jasper Fire Station | C5: 127206.86 | D5: 34039.3 | E5: 130000 | F5: 60012.3 | G5: 101233.86 | H5: 0.62782183 | I5: TRUE
A6: 20255118 | B6: Dustin Dietz | C6: 19555.76 | D6: 997.24 | E6: 20553 | F6: 12209.75 | G6: 8343.25 | H6: 0.40593831 | I6: TRUE
A7: 20255136 | B7: INS - Paul Herzog | C7: 8277.77 | D7: -1277.77 | E7: 8277.77 | F7: 4791.7 | G7: 2208.3 | H7: 0.31547143 | I7: TRUE
A8: 20255174 | B8: Judy Shobe | C8: 29206.59 | D8: 1508.04 | E8: 29206.59 | F8: 16860.76 | G8: 13853.87 | H8: 0.45105118 | I8: TRUE
A9: 20255176 | B9: Ransae Hall | C9: 15486.94 | D9: 55 | E9: 15541.94 | F9: 8538.38 | G9: 7003.56 | H9: 0.45062328 | I9: TRUE
A10: 20255177 | B10: Daron Brown | C10: 9476.93 | E10: 9476.93 | F10: 6160.74 | G10: 3316.19 | H10: 0.34992239 | I10: TRUE
A11: 20255179 | B11: Ryan Walker | C11: 20025.57 | D11: 2376 | E11: 22401.57 | F11: 11413.68 | G11: 10987.89 | H11: 0.49049643 | I11: TRUE
A12: 20255183 | B12: Barb Spurgeon | C12: 1296.78 | D12: 150 | E12: 1296.78 | F12: 661.01 | G12: 785.77 | H12: 0.54311644 | I12: TRUE
A13: 20255191 | B13: Jeff Hobbs | C13: 27975 | D13: 1100 | E13: 29075 | F13: 17240.4 | G13: 11834.6 | H13: 0.40703697 | I13: TRUE
A14: 20255196 | B14: Frank Baxter | C14: 49280.61 | D14: -1127.69 | E14: 48252.92 | F14: 30699.18 | G14: 17453.74 | H14: 0.36246483 | I14: TRUE
A15: 20255199 | B15: Sherrill Silvers | C15: 4927.85 | D15: 55 | E15: 4982.85 | F15: 2042.46 | G15: 2940.39 | H15: 0.59010205 | I15: TRUE
A16: 20255202 | B16: Dayton Dreamcenter | C16: 5540 | E16: 5540 | F16: 2050 | G16: 3490 | H16: 0.6299639 | I16: TRUE
A17: 20255204 | B17: Dee Scherer | C17: 2520 | E17: 2520 | F17: 600 | G17: 1920 | H17: 0.76190476 | I17: TRUE
A18: 20255206 | B18: William Barrett | C18: 5766.66 | E18: 5766.66 | F18: 3459.99 | G18: 2306.67 | H18: 0.40000104 | I18: TRUE
A19: 20255220 | B19: Dan Moorhead | C19: 1102.09 | E19: 1102.09 | F19: 400 | G19: 702.09 | H19: 0.63705324 | I19: TRUE
A20: 20255229 | B20: Mary Mastronicola | C20: 240 | E20: 240 | F20: 0.01 | G20: 239.99 | H20: 0.99995833 | I20: TRUE

Sheet Commission Data
A1: Lead Number | B1: Job Number | C1: Salesperson | D1: Paid | E1: Owed | F1: Override Flag
A2: 1083 | B2: 20255003 | C2: James | D2: 1883.14 | E2: 0 | F2: FALSE
A3: 1095 | B3: 20255009 | C3: James | D3: 1740.43 | E3: 0 | F3: TRUE
A4: 1105 | B4: 20255010 | C4: Drew | D4: 572.18 | E4: 143.04 | F4: FALSE
A5: 1136 | B5: 20255014 | C5: James | D5: 169.52 | E5: 0 | F5: FALSE
A6: 1143 | B6: 20255015 | C6: James | D6: 678.51 | E6: 0 | F6: FALSE
A7: 1173 | B7: 20255017 | C7: Will | D7: 0 | E7: 0 | F7: FALSE
A8: 1170 | B8: 20255018 | C8: James | D8: 1393.23 | E8: 0 | F8: TRUE
A9: 1154 | B9: 20255019 | C9: Brett | D9: 929.91 | E9: 0 | F9: FALSE
A10: 1127 | B10: 20255020 | C10: Brett | D10: 1085.61 | E10: 0 | F10: FALSE
A11: 1139 | B11: 20255021 | C11: Drew | D11: 85.71 | E11: 0 | F11: FALSE
A12: 1179 | B12: 20255022 | C12: James | D12: 516.38 | E12: 0 | F12: FALSE
A13: 1159 | B13: 20255023 | C13: Drew | D13: 568.74 | E13: 0 | F13: FALSE
... A42: 1155 | B42: 20255057 | C42: Brett | D42: 935.61 | E42: 0 | F42: FALSE
A43: 1319 | B43: 20255058 | C43: Drew | D43: 61.31 | F43: FALSE
A44: 1360 | B44: 20255059 | C44: Drew | D44: 47 | E44: 0 | F44: FALSE
A45: 1350 | B45: 20255060 | C45: James | D45: 17.5 | E45: 0 | F45: FALSE
A46: 1286 | B46: 20255061 | C46: Brett | D46: 538.36 | E46: 0 | F46: FALSE
A47: 1356 | B47: 20255062 | C47: Drew | D47: 503.03 | E47: 0 | F47: FALSE
A48: 1153 | B48: 20255063 | C48: Brett | D48: 785.59 | E48: 0 | F48: FALSE
A49: 1333 | B49: 20255064 | C49: Drew | D49: 309.2 | E49: 0 | F49: FALSE
A50: 1225 | B50: 20255065 | C50: James | D50: 1955.84 | E50: 0 | F50: TRUE
A51: 1200 | B51: 20255066 | C51: Drew | D51: 1122.45 | E51: 0 | F51: FALSE
A52: 1327 | B52: 20255067 | C52: Drew | D52: 713.49 | E52: 0 | F52: FALSE
A53: 1273 | B53: 20255068 | C53: James | D53: 1131.93 | E53: 0 | F53: FALSE
A54: 1299 | B54: 20255069 | C54: Drew | D54: 8062.31 | E54: 0 | F54: FALSE
A55: 1309 | B55: 20255070 | C55: Drew | D55: 1040.55 | E55: 0 | F55: FALSE
... A472: 1691 | B472: 20265042 | C472: Drew | D472: 0 | E472: 0 | F472: FALSE

Sheet 2026 Surveys

Sheet 2025
A1: Project # | B1: Job # | C1: Name | D1: Type | E1: Date | F1: Contract Amt $3,015,547.20 | G1: Projected Start Date | H1: Projected End Date | I1: AM | J1: ="Invoiced Total $" & TEXT(SUM(J2:J233),"#,##0.00") -> Invoiced Total $3,306,820.45 | K1: ="Amount Paid $" & TEXT(SUM(K2:K233),"#,##0.00") -> Amount Paid $3,648,737.33 | L1: ="Change Orders $" & TEXT(SUM(L2:L233),"#,##0.00") -> Change Orders $233,887.95 | M1: ="Cost $" & TEXT(SUM(M2:M233),"#,##0.00") -> Cost $1,901,675.62 | N1: ="GP $" & TEXT(SUM(N2:N233),"#,##0.00") -> GP $1,277,104.64 | O1: =AVERAGEIFS(O2:O233, O2:O233, "<>", S2:S233, TRUE) -> 0.47682031 | P1: =AVERAGEIFS(P2:P233, P2:P233, "<>", S2:S233, TRUE) -> 0.46693985 | Q1: =AVERAGEIFS(Q2:Q233, Q2:Q233, "<>", S2:S233, TRUE) -> 0.55016782 | R1: Billed | S1: Paid in Full | T1: Comm Owed | U1: Status | V1: Updated this week | W1: GP | X1: Invoiced | Y1: Contract | Z1: Change Orders | AA1: =IFERROR(__xludf.DUMMYFUNCTION("ARRAYFORMULA({ ""Manager""; IF(A2:A389="""","""", IF(IFERROR(VALUE(A2:A389),0)>=1857, ""Drew"", IF( REGEXMATCH( LOWER( TRIM( SUBSTITUTE( SUBSTITUTE( CLEAN(I2:I389), "&" CHAR(160),"" "" ), CHAR(9),"""" ) ) ), ""^drew$"" ), ""Drew"","""" ) ) ) }) "),"Manager") -> Manager | AB1: Amount Paid | AC1: Date of Last Payment
A2: 1050 | B2: 20255001 | C2: Lauren Mccoy | D2: Roofing and Siding | E2: 45664.412 | F2: 1770 | G2: 45713 | H2: 45714 | I2: Mike | J2: 1770 | K2: 1770 | L2: =if(S2=TRUE,K2-F2,"") -> 0 | M2: 607.08 | N2: =if(S2=TRUE,K2-M2,"") -> 1162.92 | O2: =IF($R2, IFERROR(IF((F2+L2)>0, (F2+L2-M2)/(F2+L2), ""), ""), "") -> 0.65701695 | P2: =IFERROR(__xludf.DUMMYFUNCTION("IF(AND($R2, NOT(REGEXMATCH(UPPER($C2), ""INS""))), IFERROR(IF((F2+L2)>0, (F2+L2-M2)/(F2+L2), """"), """"), """")"),0.6570169491525424) -> 0.65701695 | Q2: =IFERROR(__xludf.DUMMYFUNCTION("IF(AND($R2, REGEXMATCH(UPPER($C2), ""INS"")), IFERROR(IF((F2+L2)>0, (F2+L2-M2)/(F2+L2), """"), """"), """")"),"") | R2: TRUE | S2: TRUE | T2: TRUE | U2: In Billing | V2: TRUE | W2: =O2 -> 0.65701695 | X2: =J2 -> 1770 | Y2: =F2 -> 1770 | Z2: =L2 -> 0 | AA2: =IFERROR(__xludf.DUMMYFUNCTION("""COMPUTED_VALUE"""),"") | AB2: =K2 -> 1770
A3: 1074 | B3: 20255002 | C3: Dennis Hong | D3: Roofing and Siding | E3: 45674.543 | F3: 0 | G3: 45742 | H3: 45743 | I3: Adam | J3: 0 | K3: 0 | L3: =if(S3=TRUE,K3-F3,"") -> 0 | M3: 0 | N3: =if(S3=TRUE,K3-M3,"") -> 0 | O3: =IF($R3, IFERROR(IF((F3+L3)>0, (F3+L3-M3)/(F3+L3), ""), ""), "") | P3: =IFERROR(__xludf.DUMMYFUNCTION("IF(AND($R3, NOT(REGEXMATCH(UPPER($C3), ""INS""))), IFERROR(IF((F3+L3)>0, (F3+L3-M3)/(F3+L3), """"), """"), """")"),"") | Q3: =IFERROR(__xludf.DUMMYFUNCTION("IF(AND($R3, REGEXMATCH(UPPER($C3), ""INS"")), IFERROR(IF((F3+L3)>0, (F3+L3-M3)/(F3+L3), """"), """"), """")"),"") | R3: TRUE | S3: TRUE | T3: FALSE | U3: In Billing | V3: TRUE | W3: =O3 | X3: =J3 -> 0 | Y3: =F3 -> 0 | Z3: =L3 -> 0 | AA3: =IFERROR(__xludf.DUMMYFUNCTION("""COMPUTED_VALUE"""),"") | AB3: =K3 -> 0
A4: 1083 | B4: 20255003 | C4: Doug Gregory | D4: Roofing and Siding | E4: 45674.544 | F4: 45266 | G4: 45827 | H4: 45827 | I4: James | J4: 47078.44 | K4: 47078.44 | L4: =if(S4=TRUE,K4-F4,"") -> 1812.44 | M4: 38797.66 | N4: =if(S4=TRUE,K4-M4,"") -> 8280.78 | O4: =IF($R4, IFERROR(IF((F4+L4)>0, (F4+L4-M4)/(F4+L4), ""), ""), "") -> 0.17589325 | P4: =IFERROR(__xludf.DUMMYFUNCTION("IF(AND($R4, NOT(REGEXMATCH(UPPER($C4), ""INS""))), IFERROR(IF((F4+L4)>0, (F4+L4-M4)/(F4+L4), """"), """"), """")"),0.17589325389711297) -> 0.17589325 | Q4: =IFERROR(__xludf.DUMMYFUNCTION("IF(AND($R4, REGEXMATCH(UPPER($C4), ""INS"")), IFERROR(IF((F4+L4)>0, (F4+L4-M4)/(F4+L4), """"), """"), """")"),"") | R4: TRUE | S4: TRUE | T4: FALSE | U4: In Billing | V4: TRUE | W4: =O4 -> 0.17589325 | X4: =J4 -> 47078.44 | Y4: =F4 -> 45266 | Z4: =L4 -> 1812.44 | AA4: =IFERROR(__xludf.DUMMYFUNCTION("""COMPUTED_VALUE"""),"") | AB4: =K4 -> 47078.44
